Workbook
Name electronicspackagingheterogeneousintegrationandthermalmanagement: 'Official Courses'!#REF!
Name integratedcircuitsystemdesignelectronicdesignautomation: 'Official Courses'!#REF!
Name semiconductormanufacturingandglobalsupplychainmanagement: 'Official Courses'!#REF!
Name semiconductormateriralscharacterizationandprocessing: 'Official Courses'!#REF!

Sheet Updated
N1: Advanced Packaging | O1: Artificial Intelligence & Machine Learning | P1: AI Acceleration (Hardware) | Q1: Analog IC Design | R1: ASIC RTL Design | S1: Characterization & Metrology | T1: Custom Digital IC Design | U1: Data Analysis | V1: Data Center Infrastructure | W1: Design for Sustainability | X1: Design, EDA, and Digital Twins | Y1: Device and Circuit Concepts | Z1: Digital Design | AA1: Embedded Systems | AB1: Fabrication Concepts | AC1: Facilities Design | AD1: FPGA Prototyping | AE1: Functional verification of ASiC/SoC | AF1: Interconnects & Re-Distribution Layers | AG1: Lithography | AH1: Manufacturing & Control Strategies | AI1: Material Properties | AJ1: Memory design | AK1: Micro-Electro-Mechanical Systems (MEMS) | AL1: Mixed Signal IC Design | AM1: Nanoscale Materials, Systems, & Devices | AN1: Optics and Photonics | AO1: Physical layout and verification of ICs | AP1: Power Delivery | AQ1: Power Electronics | AR1: Process Analysis & Scheduling | AS1: Process Development & Assembly | AT1: Processor Design | AU1: Quality Control | AV1: Quantum Computing | AW1: Quantum Mechanics & Solid State Physics | AX1: Radiation Hardening | AY1: Reliability & Failure Analysis | AZ1: RF IC design | BA1: Health & Safety | BB1: Semiconductor Fundamentals & Device Theory | BC1: Sensors and Actuators | BD1: Statistical Analysis | BE1: Statistical Process Control | BF1: Substrates, Materials, and Encapsulation | BG1: Supply Chain Management | BH1: System on Chip Architecture | BI1: Thermal Management | BJ1: Timing Analysis | BK1: Uncertainty Analysis | BL1: VLSI Design
A2: Certificate? | B2: Course Number | C2: ID# | D2: Course | E2: Credits | F2: Primary Certificate Category | G2: Secondary Certificate Category | H2: Pre-Requisites | I2: Other Restrictions / Notes | J2: Course Description | K2: Catalog Link | L2: Additional Information | M2: Topics | N2: =COUNTIFS(N$3:N$400,"x",$A$3:$A$400,"Yes*")+COUNTIFS(N$3:N$400,"x",$A$3:$A$400,"Add*") -> 6 | O2: =COUNTIFS(O$3:O$400,"x",$A$3:$A$400,"Yes*")+COUNTIFS(O$3:O$400,"x",$A$3:$A$400,"Add*") -> 3 | P2: =COUNTIFS(P$3:P$400,"x",$A$3:$A$400,"Yes*")+COUNTIFS(P$3:P$400,"x",$A$3:$A$400,"Add*") -> 1 | Q2: =COUNTIFS(Q$3:Q$400,"x",$A$3:$A$400,"Yes*")+COUNTIFS(Q$3:Q$400,"x",$A$3:$A$400,"Add*") -> 5 | R2: =COUNTIFS(R$3:R$400,"x",$A$3:$A$400,"Yes*")+COUNTIFS(R$3:R$400,"x",$A$3:$A$400,"Add*") -> 3 | S2: =COUNTIFS(S$3:S$400,"x",$A$3:$A$400,"Yes*")+COUNTIFS(S$3:S$400,"x",$A$3:$A$400,"Add*") -> 9 | T2: =COUNTIFS(T$3:T$400,"x",$A$3:$A$400,"Yes*")+COUNTIFS(T$3:T$400,"x",$A$3:$A$400,"Add*") -> 5 | U2: =COUNTIFS(U$3:U$400,"x",$A$3:$A$400,"Yes*")+COUNTIFS(U$3:U$400,"x",$A$3:$A$400,"Add*") -> 22 | ... BL2: =COUNTIFS(BL$3:BL$400,"x",$A$3:$A$400,"Yes*")+COUNTIFS(BL$3:BL$400,"x",$A$3:$A$400,"Add*") -> 7
A3: No | B3: CHE 20500 | C3: CHE 20500 | D3: CHE 20500 Chemical Engineering Calculations | E3: =IF(_xlfn.IFNA(VLOOKUP(B3,Data!B:G,3,FALSE),"")=0, "", _xlfn.IFNA(VLOOKUP(B3,Data!B:G,3,FALSE),"")) -> 4 | F3: N/A | H3: =IF(_xlfn.IFNA(VLOOKUP(C3,Data!A:G,5,FALSE),"")=0, "Check course registration information", _xlfn.IFNA(VLOOKUP(C3,Data!A:G,5,FALSE),"")) -> ENGR 12100 or ENFY 12600 or ENGR 12600 or ENFY 13100 or ENGR 13100 or ENGR 13000 or VIP 17911 or ENGR 17911 or ENGR 16100 or EPCS 11100 or EPCS 12100 or ENFY 19500 or ENGR 19500 or ENGR 14100 or ENGR 16100) and (PHYS 17200 or (PHYS 16200 and PHYS 16300) or (ENGR 16200) and (MA 16100 or MA 16700 Minimum Grade of | J3: =IF(_xlfn.IFNA(VLOOKUP(C3,Data!A:G,6,FALSE),"")=0, "Check course registration information", _xlfn.IFNA(VLOOKUP(C3,Data!A:G,6,FALSE),"")) -> Quantitative applications of steady-state mass and energy balances to solve problems involving multi-component systems and multi-unit chemical processes. Single-component and multi-component phase equilibria, single-reaction and multiple-reaction stoichiometry, coupled mass and energy balances, chemical processes involving bypass and recycle streams | K3: =IF(_xlfn.IFNA(VLOOKUP(C3,Data!A:H,7,FALSE),"")=0, "", _xlfn.IFNA(HYPERLINK(VLOOKUP(C3,Data!A:H,7,FALSE),"Catalog Link"),"")) -> Catalog Link | L3: =IF(_xlfn.IFNA(VLOOKUP(C3,Data!A:I,8,FALSE),"")=0, "", _xlfn.IFNA(HYPERLINK(VLOOKUP(C3,Data!A:I,8,FALSE),"Additional Information"),"")) | M3: =COUNTIF(N3:BL3,"x") -> 2 | AS3: x | BI3: x
A4: No | B4: CHE 21100 | C4: CHE 21100 | D4: CHE 21100 Introductory Chemical Engineering Thermodynamics | E4: =IF(_xlfn.IFNA(VLOOKUP(B4,Data!B:G,3,FALSE),"")=0, "", _xlfn.IFNA(VLOOKUP(B4,Data!B:G,3,FALSE),"")) -> 4 | F4: N/A | H4: =IF(_xlfn.IFNA(VLOOKUP(C4,Data!A:G,5,FALSE),"")=0, "Check course registration information", _xlfn.IFNA(VLOOKUP(C4,Data!A:G,5,FALSE),"")) -> CHE 20500 and (MA 26100 or MATH 26100 or MA 18200 or MA 17400 or MA 27100 or MA 26300 or MA 17200 | J4: =IF(_xlfn.IFNA(VLOOKUP(C4,Data!A:G,6,FALSE),"")=0, "Check course registration information", _xlfn.IFNA(VLOOKUP(C4,Data!A:G,6,FALSE),"")) -> Basic principles and concepts of thermodynamics applied to chemical engineering problems; use of basic thermodynamic functions of enthalpy, entropy, free energy to solutions, phase equilibria, and chemical equilibria; thermodynamic processes and efficiencies; equations of state; and relation of macroscopic to molecular properties | K4: =IF(_xlfn.IFNA(VLOOKUP(C4,Data!A:H,7,FALSE),"")=0, "", _xlfn.IFNA(HYPERLINK(VLOOKUP(C4,Data!A:H,7,FALSE),"Catalog Link"),"")) -> Catalog Link | L4: =IF(_xlfn.IFNA(VLOOKUP(C4,Data!A:I,8,FALSE),"")=0, "", _xlfn.IFNA(HYPERLINK(VLOOKUP(C4,Data!A:I,8,FALSE),"Additional Information"),"")) | M4: =COUNTIF(N4:BL4,"x") -> 4 | S4: x | W4: x | BF4: x | BI4: x
A5: No | B5: CHE 30600 | C5: CHE 30600 | D5: CHE 30600 Design Of Staged Separation Processes | E5: =IF(_xlfn.IFNA(VLOOKUP(B5,Data!B:G,3,FALSE),"")=0, "", _xlfn.IFNA(VLOOKUP(B5,Data!B:G,3,FALSE),"")) -> 3 | F5: N/A | H5: =IF(_xlfn.IFNA(VLOOKUP(C5,Data!A:G,5,FALSE),"")=0, "Check course registration information", _xlfn.IFNA(VLOOKUP(C5,Data!A:G,5,FALSE),"")) -> CHE 20500 and CHE 21100 | J5: =IF(_xlfn.IFNA(VLOOKUP(C5,Data!A:G,6,FALSE),"")=0, "Check course registration information", _xlfn.IFNA(VLOOKUP(C5,Data!A:G,6,FALSE),"")) -> The application of equilibria and mass and energy balances for the design of staged separation processes. Use of various equilibrium data and thermodynamic principles for the design of batch and continuous distillation, absorption, stripping, and extraction systems. Stagewise calculations and graphical methods for design of binary systems. Design of multicomponent separators. Determination of stage efficiency and column size | K5: =IF(_xlfn.IFNA(VLOOKUP(C5,Data!A:H,7,FALSE),"")=0, "", _xlfn.IFNA(HYPERLINK(VLOOKUP(C5,Data!A:H,7,FALSE),"Catalog Link"),"")) -> Catalog Link | L5: =IF(_xlfn.IFNA(VLOOKUP(C5,Data!A:I,8,FALSE),"")=0, "", _xlfn.IFNA(HYPERLINK(VLOOKUP(C5,Data!A:I,8,FALSE),"Additional Information"),"")) | M5: =COUNTIF(N5:BL5,"x") -> 0
A6: Yes | B6: CHE 32000 | C6: CHE 32000 | D6: CHE 32000 Statistical Modeling And Quality Enhancement | E6: =IF(_xlfn.IFNA(VLOOKUP(B6,Data!B:G,3,FALSE),"")=0, "", _xlfn.IFNA(VLOOKUP(B6,Data!B:G,3,FALSE),"")) -> 3 | F6: Semiconductor Manufacturing and Global Supply Chain Management | H6: =IF(_xlfn.IFNA(VLOOKUP(C6,Data!A:G,5,FALSE),"")=0, "Check course registration information", _xlfn.IFNA(VLOOKUP(C6,Data!A:G,5,FALSE),"")) -> CHE 20500 or ABE 20100) and MA 26100 [concurrent ok] and (CHM 26100 or CHM 25500 [concurrent ok] or CHM 25700 [concurrent ok]) and (MA 26200 [concurrent ok] or MATH 26200 or MA 26500 [concurrent ok] or MA 35100 [concurrent ok] | J6: =IF(_xlfn.IFNA(VLOOKUP(C6,Data!A:G,6,FALSE),"")=0, "Check course registration information", _xlfn.IFNA(VLOOKUP(C6,Data!A:G,6,FALSE),"")) -> Statistical modeling methods, design of experiments, error analysis, curve fitting and regression, analysis of variance, confidence intervals, quality control and enhancement: emphasizes preparation for designing chemical engineering laboratory experiments and analyzing data | K6: =IF(_xlfn.IFNA(VLOOKUP(C6,Data!A:H,7,FALSE),"")=0, "", _xlfn.IFNA(HYPERLINK(VLOOKUP(C6,Data!A:H,7,FALSE),"Catalog Link"),"")) -> Catalog Link | L6: =IF(_xlfn.IFNA(VLOOKUP(C6,Data!A:I,8,FALSE),"")=0, "", _xlfn.IFNA(HYPERLINK(VLOOKUP(C6,Data!A:I,8,FALSE),"Additional Information"),"")) | M6: =COUNTIF(N6:BL6,"x") -> 7 | O6: x | U6: x | AH6: x | AU6: x | AY6: x | BD6: x | BK6: x
A7: No | B7: CHE 34800 | C7: CHE 34800 | D7: CHE 34800 Chemical Reaction Engineering | E7: =IF(_xlfn.IFNA(VLOOKUP(B7,Data!B:G,3,FALSE),"")=0, "", _xlfn.IFNA(VLOOKUP(B7,Data!B:G,3,FALSE),"")) -> 4 | F7: N/A | H7: =IF(_xlfn.IFNA(VLOOKUP(C7,Data!A:G,5,FALSE),"")=0, "Check course registration information", _xlfn.IFNA(VLOOKUP(C7,Data!A:G,5,FALSE),"")) -> CHE 21100 and (MA 26600 [concurrent ok] or MA 30300 [concurrent ok] or MA 36600 [concurrent ok] or ME 58100 [concurrent ok] or MA 51400 [concurrent ok] | J7: =IF(_xlfn.IFNA(VLOOKUP(C7,Data!A:G,6,FALSE),"")=0, "Check course registration information", _xlfn.IFNA(VLOOKUP(C7,Data!A:G,6,FALSE),"")) -> Application of kinetic rate equations, mass balances and energy balances to the analysis and design of chemical reactors involving homogeneous and heterogeneous chemical reactions. Chemical equilibria, kinetic rate equations for homogeneous and heterogeneously catalyzed reactions, design of ideal isothermal reactors, effects of non-isothermal operation, effects of diffusion in porous catalysts and non-ideal mixing in continuous flow reactors | K7: =IF(_xlfn.IFNA(VLOOKUP(C7,Data!A:H,7,FALSE),"")=0, "", _xlfn.IFNA(HYPERLINK(VLOOKUP(C7,Data!A:H,7,FALSE),"Catalog Link"),"")) -> Catalog Link | L7: =IF(_xlfn.IFNA(VLOOKUP(C7,Data!A:I,8,FALSE),"")=0, "", _xlfn.IFNA(HYPERLINK(VLOOKUP(C7,Data!A:I,8,FALSE),"Additional Information"),"")) | M7: =COUNTIF(N7:BL7,"x") -> 0
A8: No | B8: CHE 37700 | C8: CHE 37700 | D8: CHE 37700 Momentum Transfer | E8: =IF(_xlfn.IFNA(VLOOKUP(B8,Data!B:G,3,FALSE),"")=0, "", _xlfn.IFNA(VLOOKUP(B8,Data!B:G,3,FALSE),"")) -> 4 | F8: N/A | H8: =IF(_xlfn.IFNA(VLOOKUP(C8,Data!A:G,5,FALSE),"")=0, "Check course registration information", _xlfn.IFNA(VLOOKUP(C8,Data!A:G,5,FALSE),"")) -> CHE 21100 and (MA 26600 [concurrent ok] or MA 30300 [concurrent ok] or MA 36600 [concurrent ok] or MA 51400 [concurrent ok] or ME 58100 [concurrent ok] | J8: =IF(_xlfn.IFNA(VLOOKUP(C8,Data!A:G,6,FALSE),"")=0, "Check course registration information", _xlfn.IFNA(VLOOKUP(C8,Data!A:G,6,FALSE),"")) -> Differential (microscopic) and integral (macroscopic) mass, momentum, and energy balances. Newtonian and non-Newtonian fluids. Fluid statics. One-dimensional steady and transient laminar flows. Turbulence. Dimensional analysis and similarity. Friction factors and drag coefficients. Applications to engineering analysis of practical problems. Introduction to numerical analysis and visualization of flows | K8: =IF(_xlfn.IFNA(VLOOKUP(C8,Data!A:H,7,FALSE),"")=0, "", _xlfn.IFNA(HYPERLINK(VLOOKUP(C8,Data!A:H,7,FALSE),"Catalog Link"),"")) -> Catalog Link | L8: =IF(_xlfn.IFNA(VLOOKUP(C8,Data!A:I,8,FALSE),"")=0, "", _xlfn.IFNA(HYPERLINK(VLOOKUP(C8,Data!A:I,8,FALSE),"Additional Information"),"")) | M8: =COUNTIF(N8:BL8,"x") -> 1 | BI8: x
A9: Yes | B9: CHE 37800 | C9: CHE 37800 | D9: CHE 37800 Heat And Mass Transfer | E9: =IF(_xlfn.IFNA(VLOOKUP(B9,Data!B:G,3,FALSE),"")=0, "", _xlfn.IFNA(VLOOKUP(B9,Data!B:G,3,FALSE),"")) -> 4 | F9: Semiconductor Materials, Characterization, and Processing | H9: =IF(_xlfn.IFNA(VLOOKUP(C9,Data!A:G,5,FALSE),"")=0, "Check course registration information", _xlfn.IFNA(VLOOKUP(C9,Data!A:G,5,FALSE),"")) -> CHE 21100 and CHE 37700 | J9: =IF(_xlfn.IFNA(VLOOKUP(C9,Data!A:G,6,FALSE),"")=0, "Check course registration information", _xlfn.IFNA(VLOOKUP(C9,Data!A:G,6,FALSE),"")) -> Macroscopic and differential energy balances. Heat transfer coefficients for free and forced convection and phase change. Conductive and radiative heat transfer. Applications to heat transfer equipment design and compressible fluid flow. Macroscopic and differential species balances. Mass transfer coefficients and analogies. Mass transfer with and without chemical reaction. Mass transfer equipment design | K9: =IF(_xlfn.IFNA(VLOOKUP(C9,Data!A:H,7,FALSE),"")=0, "", _xlfn.IFNA(HYPERLINK(VLOOKUP(C9,Data!A:H,7,FALSE),"Catalog Link"),"")) -> Catalog Link | L9: =IF(_xlfn.IFNA(VLOOKUP(C9,Data!A:I,8,FALSE),"")=0, "", _xlfn.IFNA(HYPERLINK(VLOOKUP(C9,Data!A:I,8,FALSE),"Additional Information"),"")) | M9: =COUNTIF(N9:BL9,"x") -> 2 | V9: x | BI9: x
A10: Yes | B10: CHE 42000 | C10: CHE 42000 | D10: CHE 42000 Process Safety Management And Analysis | E10: =IF(_xlfn.IFNA(VLOOKUP(B10,Data!B:G,3,FALSE),"")=0, "", _xlfn.IFNA(VLOOKUP(B10,Data!B:G,3,FALSE),"")) -> 3 | F10: Semiconductor Materials, Characterization, and Processing | H10: =IF(_xlfn.IFNA(VLOOKUP(C10,Data!A:G,5,FALSE),"")=0, "Check course registration information", _xlfn.IFNA(VLOOKUP(C10,Data!A:G,5,FALSE),"")) -> CHE 34800 [concurrent ok] and CHE 37800 [concurrent ok] | J10: =IF(_xlfn.IFNA(VLOOKUP(C10,Data!A:G,6,FALSE),"")=0, "Check course registration information", _xlfn.IFNA(VLOOKUP(C10,Data!A:G,6,FALSE),"")) -> Develop knowledge of process safety management and analysis in the process industries, including hazard identification, hazard analysis and risk management | K10: =IF(_xlfn.IFNA(VLOOKUP(C10,Data!A:H,7,FALSE),"")=0, "", _xlfn.IFNA(HYPERLINK(VLOOKUP(C10,Data!A:H,7,FALSE),"Catalog Link"),"")) -> Catalog Link | L10: =IF(_xlfn.IFNA(VLOOKUP(C10,Data!A:I,8,FALSE),"")=0, "", _xlfn.IFNA(HYPERLINK(VLOOKUP(C10,Data!A:I,8,FALSE),"Additional Information"),"")) | M10: =COUNTIF(N10:BL10,"x") -> 4 | AH10: x | AS10: x | AY10: x | BI10: x
A11: No | B11: CHE 43500 | C11: CHE 43500 | D11: CHE 43500 Chemical Engineering Laboratory | E11: =IF(_xlfn.IFNA(VLOOKUP(B11,Data!B:G,3,FALSE),"")=0, "", _xlfn.IFNA(VLOOKUP(B11,Data!B:G,3,FALSE),"")) -> 4 | F11: N/A | H11: =IF(_xlfn.IFNA(VLOOKUP(C11,Data!A:G,5,FALSE),"")=0, "Check course registration information", _xlfn.IFNA(VLOOKUP(C11,Data!A:G,5,FALSE),"")) -> CHE 32000 and CHE 34800 and CHE 37800 and CHE 30600 | J11: =IF(_xlfn.IFNA(VLOOKUP(C11,Data!A:G,6,FALSE),"")=0, "Check course registration information", _xlfn.IFNA(VLOOKUP(C11,Data!A:G,6,FALSE),"")) -> Quantitative experimental study of projects involving problems in fluid mechanics and heat and mass transfer or operation and evaluation of equipment; projects include analysis and data-based design of operations involving mass transfer such as distillation, absorption, drying, humidification, etc.; study of rates and equilibria in simple chemical reaction systems; study of chemical processes; application of methods of data analysis in practice; some library work; emphasis on group work, report writing, and oral communication | K11: =IF(_xlfn.IFNA(VLOOKUP(C11,Data!A:H,7,FALSE),"")=0, "", _xlfn.IFNA(HYPERLINK(VLOOKUP(C11,Data!A:H,7,FALSE),"Catalog Link"),"")) -> Catalog Link | L11: =IF(_xlfn.IFNA(VLOOKUP(C11,Data!A:I,8,FALSE),"")=0, "", _xlfn.IFNA(HYPERLINK(VLOOKUP(C11,Data!A:I,8,FALSE),"Additional Information"),"")) | M11: =COUNTIF(N11:BL11,"x") -> 0
A12: No | B12: CHE 45000 | C12: CHE 45000 | D12: CHE 45000 Design And Analysis Of Processing Systems | E12: =IF(_xlfn.IFNA(VLOOKUP(B12,Data!B:G,3,FALSE),"")=0, "", _xlfn.IFNA(VLOOKUP(B12,Data!B:G,3,FALSE),"")) -> 4 | F12: N/A | H12: =IF(_xlfn.IFNA(VLOOKUP(C12,Data!A:G,5,FALSE),"")=0, "Check course registration information", _xlfn.IFNA(VLOOKUP(C12,Data!A:G,5,FALSE),"")) -> CHE 30600 and CHE 37800 and CHE 42000 and CHE 45600 and CHE 43500 [concurrent ok] | J12: =IF(_xlfn.IFNA(VLOOKUP(C12,Data!A:G,6,FALSE),"")=0, "Check course registration information", _xlfn.IFNA(VLOOKUP(C12,Data!A:G,6,FALSE),"")) -> Use of process synthesis methods and concepts; detailed design of unit operation equipment, the economics of chemical plants and flow sheet optimization methods. Synthesize, develop, and evaluate a preliminary design of a chemical process that meets market requirements for a specific product. Analysis of design alternatives using case studies and optimization methods | K12: =IF(_xlfn.IFNA(VLOOKUP(C12,Data!A:H,7,FALSE),"")=0, "", _xlfn.IFNA(HYPERLINK(VLOOKUP(C12,Data!A:H,7,FALSE),"Catalog Link"),"")) -> Catalog Link | L12: =IF(_xlfn.IFNA(VLOOKUP(C12,Data!A:I,8,FALSE),"")=0, "", _xlfn.IFNA(HYPERLINK(VLOOKUP(C12,Data!A:I,8,FALSE),"Additional Information"),"")) | M12: =COUNTIF(N12:BL12,"x") -> 3 | X12: x | AS12: x | AY12: x
A13: Yes | B13: CHE 45600 | C13: CHE 45600 | D13: CHE 45600 Process Dynamics And Control | E13: =IF(_xlfn.IFNA(VLOOKUP(B13,Data!B:G,3,FALSE),"")=0, "", _xlfn.IFNA(VLOOKUP(B13,Data!B:G,3,FALSE),"")) -> 3 | F13: Semiconductor Materials, Characterization, and Processing | H13: =IF(_xlfn.IFNA(VLOOKUP(C13,Data!A:G,5,FALSE),"")=0, "Check course registration information", _xlfn.IFNA(VLOOKUP(C13,Data!A:G,5,FALSE),"")) -> CHE 37700 and CHE 34800 [concurrent ok] and CHE 37800 [concurrent ok] | J13: =IF(_xlfn.IFNA(VLOOKUP(C13,Data!A:G,6,FALSE),"")=0, "Check course registration information", _xlfn.IFNA(VLOOKUP(C13,Data!A:G,6,FALSE),"")) -> Dynamic response and control of chemical processing equipment, such as heat exchangers, chemical reactors, and absorption towers. Use is made of fundamental techniques of servomechanism theory, such as block diagrams, transfer functions, and frequency response. Introduction to advanced control techniques | K13: =IF(_xlfn.IFNA(VLOOKUP(C13,Data!A:H,7,FALSE),"")=0, "", _xlfn.IFNA(HYPERLINK(VLOOKUP(C13,Data!A:H,7,FALSE),"Catalog Link"),"")) -> Catalog Link | L13: =IF(_xlfn.IFNA(VLOOKUP(C13,Data!A:I,8,FALSE),"")=0, "", _xlfn.IFNA(HYPERLINK(VLOOKUP(C13,Data!A:I,8,FALSE),"Additional Information"),"")) | M13: =COUNTIF(N13:BL13,"x") -> 4 | X13: x | AH13: x | AY13: x | BE13: x
A14: No | B14: CHE 53600 | C14: CHE 53600 | D14: CHE 53600 Particulate Systems | E14: =IF(_xlfn.IFNA(VLOOKUP(B14,Data!B:G,3,FALSE),"")=0, "", _xlfn.IFNA(VLOOKUP(B14,Data!B:G,3,FALSE),"")) -> 3 | F14: N/A | H14: =IF(_xlfn.IFNA(VLOOKUP(C14,Data!A:G,5,FALSE),"")=0, "Check course registration information", _xlfn.IFNA(VLOOKUP(C14,Data!A:G,5,FALSE),"")) -> CHE 37700 | J14: =IF(_xlfn.IFNA(VLOOKUP(C14,Data!A:G,6,FALSE),"")=0, "Check course registration information", _xlfn.IFNA(VLOOKUP(C14,Data!A:G,6,FALSE),"")) -> A broad overview of the fundamental concepts in particulate systems including particle characterization, particle size measurement, sedimentation, fluidization, gas and liquid conveying, particle storage, fluid-particle separation, particle size enlargement and reduction, particle mixing and hazards associated with the handling of particulate solids. Practical applications are emphasized, with a focus on how particles behave differently than fluids | K14: =IF(_xlfn.IFNA(VLOOKUP(C14,Data!A:H,7,FALSE),"")=0, "", _xlfn.IFNA(HYPERLINK(VLOOKUP(C14,Data!A:H,7,FALSE),"Catalog Link"),"")) -> Catalog Link | L14: =IF(_xlfn.IFNA(VLOOKUP(C14,Data!A:I,8,FALSE),"")=0, "", _xlfn.IFNA(HYPERLINK(VLOOKUP(C14,Data!A:I,8,FALSE),"Additional Information"),"")) | M14: =COUNTIF(N14:BL14,"x") -> 0
A15: No | B15: CHE 53800 | C15: CHE 53800 | D15: CHE 53800 Design And Processing Of Particulate Products | E15: =IF(_xlfn.IFNA(VLOOKUP(B15,Data!B:G,3,FALSE),"")=0, "", _xlfn.IFNA(VLOOKUP(B15,Data!B:G,3,FALSE),"")) -> 3 | F15: N/A | H15: =IF(_xlfn.IFNA(VLOOKUP(C15,Data!A:G,5,FALSE),"")=0, "Check course registration information", _xlfn.IFNA(VLOOKUP(C15,Data!A:G,5,FALSE),"")) -> CHE 34800 or CHE 37800 | J15: =IF(_xlfn.IFNA(VLOOKUP(C15,Data!A:G,6,FALSE),"")=0, "Check course registration information", _xlfn.IFNA(VLOOKUP(C15,Data!A:G,6,FALSE),"")) -> Characterization particulate systems, use of population balances to describe processes that make or transform particles, applications in important unit processes including crystallization, granulation, milling, aerosol processes | K15: =IF(_xlfn.IFNA(VLOOKUP(C15,Data!A:H,7,FALSE),"")=0, "", _xlfn.IFNA(HYPERLINK(VLOOKUP(C15,Data!A:H,7,FALSE),"Catalog Link"),"")) -> Catalog Link | L15: =IF(_xlfn.IFNA(VLOOKUP(C15,Data!A:I,8,FALSE),"")=0, "", _xlfn.IFNA(HYPERLINK(VLOOKUP(C15,Data!A:I,8,FALSE),"Additional Information"),"")) | M15: =COUNTIF(N15:BL15,"x") -> 0
A16: Yes | B16: CHE 54000 | C16: CHE 54000 | D16: CHE 54000 Transport Penomena | E16: =IF(_xlfn.IFNA(VLOOKUP(B16,Data!B:G,3,FALSE),"")=0, "", _xlfn.IFNA(VLOOKUP(B16,Data!B:G,3,FALSE),"")) -> 3 | F16: Semiconductor Materials, Characterization, and Processing | H16: =IF(_xlfn.IFNA(VLOOKUP(C16,Data!A:G,5,FALSE),"")=0, "Check course registration information", _xlfn.IFNA(VLOOKUP(C16,Data!A:G,5,FALSE),"")) -> CHE 37800 | J16: =IF(_xlfn.IFNA(VLOOKUP(C16,Data!A:G,6,FALSE),"")=0, "Check course registration information", _xlfn.IFNA(VLOOKUP(C16,Data!A:G,6,FALSE),"")) -> Continuation of CHE 37700 and 37800. Topics in fluid mechanics, heat transfer and mass transfer including unsteady state transport problems, stream functions, potential flow, hydrodynamic and thermal layers, turbulence, and multicomponent diffusion | K16: =IF(_xlfn.IFNA(VLOOKUP(C16,Data!A:H,7,FALSE),"")=0, "", _xlfn.IFNA(HYPERLINK(VLOOKUP(C16,Data!A:H,7,FALSE),"Catalog Link"),"")) -> Catalog Link | L16: =IF(_xlfn.IFNA(VLOOKUP(C16,Data!A:I,8,FALSE),"")=0, "", _xlfn.IFNA(HYPERLINK(VLOOKUP(C16,Data!A:I,8,FALSE),"Additional Information"),"")) | M16: =COUNTIF(N16:BL16,"x") -> 3 | V16: x | AH16: x | BI16: x
A17: No | B17: CHE 54300 | C17: CHE 54300 | D17: CHE 54300 Polym Reaction Engr & Reactor Analy | E17: =IF(_xlfn.IFNA(VLOOKUP(B17,Data!B:G,3,FALSE),"")=0, "", _xlfn.IFNA(VLOOKUP(B17,Data!B:G,3,FALSE),"")) -> 3 | F17: N/A | H17: =IF(_xlfn.IFNA(VLOOKUP(C17,Data!A:G,5,FALSE),"")=0, "Check course registration information", _xlfn.IFNA(VLOOKUP(C17,Data!A:G,5,FALSE),"")) -> CHE 34800 | J17: =IF(_xlfn.IFNA(VLOOKUP(C17,Data!A:G,6,FALSE),"")=0, "Check course registration information", _xlfn.IFNA(VLOOKUP(C17,Data!A:G,6,FALSE),"")) -> Polymerization kinetics, polycondensation, gelation, radical polymerization, ionic polymerization, copolymerizations, Ziegler-Natta polymerizations, polymerization in bulk, solution, suspension and emulsion, modeling, stochastic processes, Z-transforms, batch, CSTR and tubular reactors, stability analysis, computer control, separation, and drying | K17: =IF(_xlfn.IFNA(VLOOKUP(C17,Data!A:H,7,FALSE),"")=0, "", _xlfn.IFNA(HYPERLINK(VLOOKUP(C17,Data!A:H,7,FALSE),"Catalog Link"),"")) -> Catalog Link | L17: =IF(_xlfn.IFNA(VLOOKUP(C17,Data!A:I,8,FALSE),"")=0, "", _xlfn.IFNA(HYPERLINK(VLOOKUP(C17,Data!A:I,8,FALSE),"Additional Information"),"")) | M17: =COUNTIF(N17:BL17,"x") -> 2 | W17: x | BF17: x
A18: Yes | B18: CHE 54400 | C18: CHE 54400 | D18: CHE 54400 Struct & Behav of Polymer Sys | E18: =IF(_xlfn.IFNA(VLOOKUP(B18,Data!B:G,3,FALSE),"")=0, "", _xlfn.IFNA(VLOOKUP(B18,Data!B:G,3,FALSE),"")) -> 3 | F18: Semiconductor Materials, Characterization, and Processing | H18: =IF(_xlfn.IFNA(VLOOKUP(C18,Data!A:G,5,FALSE),"")=0, "Check course registration information", _xlfn.IFNA(VLOOKUP(C18,Data!A:G,5,FALSE),"")) -> CHM 26200 or CHM 37000 | J18: =IF(_xlfn.IFNA(VLOOKUP(C18,Data!A:G,6,FALSE),"")=0, "Check course registration information", _xlfn.IFNA(VLOOKUP(C18,Data!A:G,6,FALSE),"")) -> Statistical mechanics of chain molecules, thermodynamics of polymer solutions, phase separations, experimental methods of molecular weight determination, crystallization of polymers, polymer physics, rubber elasticity, viscoelasticity | K18: =IF(_xlfn.IFNA(VLOOKUP(C18,Data!A:H,7,FALSE),"")=0, "", _xlfn.IFNA(HYPERLINK(VLOOKUP(C18,Data!A:H,7,FALSE),"Catalog Link"),"")) -> Catalog Link | L18: =IF(_xlfn.IFNA(VLOOKUP(C18,Data!A:I,8,FALSE),"")=0, "", _xlfn.IFNA(HYPERLINK(VLOOKUP(C18,Data!A:I,8,FALSE),"Additional Information"),"")) | M18: =COUNTIF(N18:BL18,"x") -> 5 | S18: x | W18: x | AH18: x | AI18: x | BF18: x
A19: No | B19: CHE 55000 | C19: CHE 55000 | D19: CHE 55000 Optimization In Chemical Engineering | E19: =IF(_xlfn.IFNA(VLOOKUP(B19,Data!B:G,3,FALSE),"")=0, "", _xlfn.IFNA(VLOOKUP(B19,Data!B:G,3,FALSE),"")) -> 3 | F19: N/A | H19: =IF(_xlfn.IFNA(VLOOKUP(C19,Data!A:G,5,FALSE),"")=0, "Check course registration information", _xlfn.IFNA(VLOOKUP(C19,Data!A:G,5,FALSE),"")) -> Senior status and above | J19: =IF(_xlfn.IFNA(VLOOKUP(C19,Data!A:G,6,FALSE),"")=0, "Check course registration information", _xlfn.IFNA(VLOOKUP(C19,Data!A:G,6,FALSE),"")) -> Survey of the basic computational tools for solving nonlinear constrained and unconstrained optimization problems. Emphasis on methods applicable to problems arising in chemical plant design, process operations and scheduling, parameter estimation, and waste energy reutilization | K19: =IF(_xlfn.IFNA(VLOOKUP(C19,Data!A:H,7,FALSE),"")=0, "", _xlfn.IFNA(HYPERLINK(VLOOKUP(C19,Data!A:H,7,FALSE),"Catalog Link"),"")) -> Catalog Link | L19: =IF(_xlfn.IFNA(VLOOKUP(C19,Data!A:I,8,FALSE),"")=0, "", _xlfn.IFNA(HYPERLINK(VLOOKUP(C19,Data!A:I,8,FALSE),"Additional Information"),"")) | M19: =COUNTIF(N19:BL19,"x") -> 2 | O19: x | AS19: x
A20: No | B20: CHE 55500 | C20: CHE 55500 | D20: CHE 55500 Computer Integrated Process Operations | E20: =IF(_xlfn.IFNA(VLOOKUP(B20,Data!B:G,3,FALSE),"")=0, "", _xlfn.IFNA(VLOOKUP(B20,Data!B:G,3,FALSE),"")) -> 3 | F20: N/A | H20: =IF(_xlfn.IFNA(VLOOKUP(C20,Data!A:G,5,FALSE),"")=0, "Check course registration information", _xlfn.IFNA(VLOOKUP(C20,Data!A:G,5,FALSE),"")) -> Senior status and above | J20: =IF(_xlfn.IFNA(VLOOKUP(C20,Data!A:G,6,FALSE),"")=0, "Check course registration information", _xlfn.IFNA(VLOOKUP(C20,Data!A:G,6,FALSE),"")) -> Introduction to computer-aided process operations management. Topics include: process monitoring, regulatory control, data reconciliation, unit and plant-wide optimization, process fault diagnosis, supervisory control, planning, and scheduling. A design project involving a unified application of the presented methodologies is taken from a published industrial benchmark problem | K20: =IF(_xlfn.IFNA(VLOOKUP(C20,Data!A:H,7,FALSE),"")=0, "", _xlfn.IFNA(HYPERLINK(VLOOKUP(C20,Data!A:H,7,FALSE),"Catalog Link"),"")) -> Catalog Link | L20: =IF(_xlfn.IFNA(VLOOKUP(C20,Data!A:I,8,FALSE),"")=0, "", _xlfn.IFNA(HYPERLINK(VLOOKUP(C20,Data!A:I,8,FALSE),"Additional Information"),"")) | M20: =COUNTIF(N20:BL20,"x") -> 2 | O20: x | AS20: x
A21: No | B21: CHE 55700 | C21: CHE 55700 | D21: CHE 55700 Intelligent Systems In Process Engineering | E21: =IF(_xlfn.IFNA(VLOOKUP(B21,Data!B:G,3,FALSE),"")=0, "", _xlfn.IFNA(VLOOKUP(B21,Data!B:G,3,FALSE),"")) -> 3 | F21: N/A | H21: =IF(_xlfn.IFNA(VLOOKUP(C21,Data!A:G,5,FALSE),"")=0, "Check course registration information", _xlfn.IFNA(VLOOKUP(C21,Data!A:G,5,FALSE),"")) -> Senior status and above | J21: =IF(_xlfn.IFNA(VLOOKUP(C21,Data!A:G,6,FALSE),"")=0, "Check course registration information", _xlfn.IFNA(VLOOKUP(C21,Data!A:G,6,FALSE),"")) -> Introduction to artificial intelligence concepts and techniques and their application to important problems in process systems engineering. Topics covered include: introduction to artificial intelligence, knowledge representation and search, knowledge-based systems, neural networks, genetic algorithms, inexact reasoning techniques, industrial case studies in process fault diagnosis and control, design and synthesis, planning and scheduling, AI languages, tools, and environments | K21: =IF(_xlfn.IFNA(VLOOKUP(C21,Data!A:H,7,FALSE),"")=0, "", _xlfn.IFNA(HYPERLINK(VLOOKUP(C21,Data!A:H,7,FALSE),"Catalog Link"),"")) -> Catalog Link | L21: =IF(_xlfn.IFNA(VLOOKUP(C21,Data!A:I,8,FALSE),"")=0, "", _xlfn.IFNA(HYPERLINK(VLOOKUP(C21,Data!A:I,8,FALSE),"Additional Information"),"")) | M21: =COUNTIF(N21:BL21,"x") -> 0
A22: No | B22: CHE 55800 | C22: CHE 55800 | D22: CHE 55800 Rate Control Sep Process | E22: =IF(_xlfn.IFNA(VLOOKUP(B22,Data!B:G,3,FALSE),"")=0, "", _xlfn.IFNA(VLOOKUP(B22,Data!B:G,3,FALSE),"")) -> 3 | F22: N/A | H22: =IF(_xlfn.IFNA(VLOOKUP(C22,Data!A:G,5,FALSE),"")=0, "Check course registration information", _xlfn.IFNA(VLOOKUP(C22,Data!A:G,5,FALSE),"")) -> CHE 30600 or CHE 37800 | J22: =IF(_xlfn.IFNA(VLOOKUP(C22,Data!A:G,6,FALSE),"")=0, "Check course registration information", _xlfn.IFNA(VLOOKUP(C22,Data!A:G,6,FALSE),"")) -> Rate-controlled separation processes based on solute movement (adsorption, chromatography and ion exchange), membranes (reverse osmosis, ultrafiltration, and gas permeation), and crystallization | K22: =IF(_xlfn.IFNA(VLOOKUP(C22,Data!A:H,7,FALSE),"")=0, "", _xlfn.IFNA(HYPERLINK(VLOOKUP(C22,Data!A:H,7,FALSE),"Catalog Link"),"")) -> Catalog Link | L22: =IF(_xlfn.IFNA(VLOOKUP(C22,Data!A:I,8,FALSE),"")=0, "", _xlfn.IFNA(HYPERLINK(VLOOKUP(C22,Data!A:I,8,FALSE),"Additional Information"),"")) | M22: =COUNTIF(N22:BL22,"x") -> 0
A23: No | B23: CHE 56000 | C23: CHE 56000 | D23: CHE 56000 Introduction To Energy Storage Systems | E23: 3 | F23: N/A | H23: =IF(_xlfn.IFNA(VLOOKUP(C23,Data!A:G,5,FALSE),"")=0, "Check course registration information", _xlfn.IFNA(VLOOKUP(C23,Data!A:G,5,FALSE),"")) -> Senior status and above | J23: =IF(_xlfn.IFNA(VLOOKUP(C23,Data!A:G,6,FALSE),"")=0, "Check course registration information", _xlfn.IFNA(VLOOKUP(C23,Data!A:G,6,FALSE),"")) -> Energy Storage Systems Laboratory course is designed to introduce fundamentals of electrochemistry and electrochemical engineering of rechargeable lithium ion batteries (LIBs) to undergraduate and graduate students. The course will be reviewing working principles of LIBs, hands-on experience on their assembly, charge-discharge testing, data analysis and related safety aspects. Strong emphasis will be given on the Li-ion battery technology, nanotechnology implementation and the materials design. Beyond conventional Li-ion systems and Pb-acid batteries, next generation Na-ion, K-ion and Li-S batteries will be discussed and designed. Students will be fabricating and testing high energy density batteries utilizing engineered electrodes, electrolytes and separators. Broader perspectives on sustainable, cost effective, longer lasting battery manufacturing will be provided. | K23: =IF(_xlfn.IFNA(VLOOKUP(C23,Data!A:H,7,FALSE),"")=0, "", _xlfn.IFNA(HYPERLINK(VLOOKUP(C23,Data!A:H,7,FALSE),"Catalog Link"),"")) -> Catalog Link | L23: =IF(_xlfn.IFNA(VLOOKUP(C23,Data!A:I,8,FALSE),"")=0, "", _xlfn.IFNA(HYPERLINK(VLOOKUP(C23,Data!A:I,8,FALSE),"Additional Information"),"")) | M23: =COUNTIF(N23:BL23,"x") -> 0
A24: No | B24: CHE 56400 | C24: CHE 56400 | D24: CHE 56400 Organic Electronic Materials And Devices | E24: =IF(_xlfn.IFNA(VLOOKUP(B24,Data!B:G,3,FALSE),"")=0, "", _xlfn.IFNA(VLOOKUP(B24,Data!B:G,3,FALSE),"")) -> 3 | F24: Semiconductor Materials, Characterization, and Processing | H24: =IF(_xlfn.IFNA(VLOOKUP(C24,Data!A:G,5,FALSE),"")=0, "Check course registration information", _xlfn.IFNA(VLOOKUP(C24,Data!A:G,5,FALSE),"")) -> CHM 26100 or CHM 25500 or CHM 25700 | J24: =IF(_xlfn.IFNA(VLOOKUP(C24,Data!A:G,6,FALSE),"")=0, "Check course registration information", _xlfn.IFNA(VLOOKUP(C24,Data!A:G,6,FALSE),"")) -> This course introduces the synthesis, optoelectronic properties, transport physics, and device operation of organic and hybrid electronic materials and devices. This course will review how the molecular architecture of small molecule and polymer semiconductors can be turned to alter the optoelectronic properties of the materials in solution and in the solid state. A number of relevant materials interactions will be covered, including: photoexcitation and recombination, intermolecular charge transport mechanisms, and energy transfer processes. Additionally, we will observe how these processes are relevant to applications such as organic field-effect transistors (OFETs), organic light-emitting diodes (OLEDs), organic photovoltaic (OPV) devices, and organic memory elements. Finally, a new type of organic-inorganic hybrid material called hybrid halide perovskite will be introduced | K24: =IF(_xlfn.IFNA(VLOOKUP(C24,Data!A:H,7,FALSE),"")=0, "", _xlfn.IFNA(HYPERLINK(VLOOKUP(C24,Data!A:H,7,FALSE),"Catalog Link"),"")) -> Catalog Link | L24: =IF(_xlfn.IFNA(VLOOKUP(C24,Data!A:I,8,FALSE),"")=0, "", _xlfn.IFNA(HYPERLINK(VLOOKUP(C24,Data!A:I,8,FALSE),"Additional Information"),"")) | M24: =COUNTIF(N24:BL24,"x") -> 3 | S24: x | W24: x | BF24: x
A25: No | B25: CHE 59700 | C25: CHE 59700 | D25: CHE 59700 Crystallization Systems in Engr | E25: =IF(_xlfn.IFNA(VLOOKUP(B25,Data!B:G,3,FALSE),"")=0, "", _xlfn.IFNA(VLOOKUP(B25,Data!B:G,3,FALSE),"")) | F25: N/A | H25: =IF(_xlfn.IFNA(VLOOKUP(C25,Data!A:G,5,FALSE),"")=0, "Check course registration information", _xlfn.IFNA(VLOOKUP(C25,Data!A:G,5,FALSE),"")) -> Check course registration information | J25: =IF(_xlfn.IFNA(VLOOKUP(C25,Data!A:G,6,FALSE),"")=0, "Check course registration information", _xlfn.IFNA(VLOOKUP(C25,Data!A:G,6,FALSE),"")) -> Check course registration information | K25: =IF(_xlfn.IFNA(VLOOKUP(C25,Data!A:H,7,FALSE),"")=0, "", _xlfn.IFNA(HYPERLINK(VLOOKUP(C25,Data!A:H,7,FALSE),"Catalog Link"),"")) -> Catalog Link | L25: =IF(_xlfn.IFNA(VLOOKUP(C25,Data!A:I,8,FALSE),"")=0, "", _xlfn.IFNA(HYPERLINK(VLOOKUP(C25,Data!A:I,8,FALSE),"Additional Information"),"")) | M25: =COUNTIF(N25:BL25,"x") -> 1 | BF25: x
A26: No | B26: CHE 59700 | C26: CHE 59700-1 | D26: CHE 59700 Industial Catalytic Processes | E26: =IF(_xlfn.IFNA(VLOOKUP(B26,Data!B:G,3,FALSE),"")=0, "", _xlfn.IFNA(VLOOKUP(B26,Data!B:G,3,FALSE),"")) | F26: N/A | H26: =IF(_xlfn.IFNA(VLOOKUP(C26,Data!A:G,5,FALSE),"")=0, "Check course registration information", _xlfn.IFNA(VLOOKUP(C26,Data!A:G,5,FALSE),"")) -> Check course registration information | J26: =IF(_xlfn.IFNA(VLOOKUP(C26,Data!A:G,6,FALSE),"")=0, "Check course registration information", _xlfn.IFNA(VLOOKUP(C26,Data!A:G,6,FALSE),"")) -> Check course registration information | K26: =IF(_xlfn.IFNA(VLOOKUP(C26,Data!A:H,7,FALSE),"")=0, "", _xlfn.IFNA(HYPERLINK(VLOOKUP(C26,Data!A:H,7,FALSE),"Catalog Link"),"")) -> Catalog Link | L26: =IF(_xlfn.IFNA(VLOOKUP(C26,Data!A:I,8,FALSE),"")=0, "", _xlfn.IFNA(HYPERLINK(VLOOKUP(C26,Data!A:I,8,FALSE),"Additional Information"),"")) | M26: =COUNTIF(N26:BL26,"x") -> 0
A27: No | B27: CHE 59700 | C27: CHE 59700-2 | D27: CHE 59700 Industrial Chemical Technology | E27: =IF(_xlfn.IFNA(VLOOKUP(B27,Data!B:G,3,FALSE),"")=0, "", _xlfn.IFNA(VLOOKUP(B27,Data!B:G,3,FALSE),"")) | F27: N/A | H27: =IF(_xlfn.IFNA(VLOOKUP(C27,Data!A:G,5,FALSE),"")=0, "Check course registration information", _xlfn.IFNA(VLOOKUP(C27,Data!A:G,5,FALSE),"")) -> Check course registration information | J27: =IF(_xlfn.IFNA(VLOOKUP(C27,Data!A:G,6,FALSE),"")=0, "Check course registration information", _xlfn.IFNA(VLOOKUP(C27,Data!A:G,6,FALSE),"")) -> Check course registration information | K27: =IF(_xlfn.IFNA(VLOOKUP(C27,Data!A:H,7,FALSE),"")=0, "", _xlfn.IFNA(HYPERLINK(VLOOKUP(C27,Data!A:H,7,FALSE),"Catalog Link"),"")) -> Catalog Link | L27: =IF(_xlfn.IFNA(VLOOKUP(C27,Data!A:I,8,FALSE),"")=0, "", _xlfn.IFNA(HYPERLINK(VLOOKUP(C27,Data!A:I,8,FALSE),"Additional Information"),"")) | M27: =COUNTIF(N27:BL27,"x") -> 0
A28: No | B28: CHE 59700 | C28: CHE 59700-3 | D28: CHE 59700 Org Elec Materials and Devices | E28: =IF(_xlfn.IFNA(VLOOKUP(B28,Data!B:G,3,FALSE),"")=0, "", _xlfn.IFNA(VLOOKUP(B28,Data!B:G,3,FALSE),"")) | F28: N/A | H28: =IF(_xlfn.IFNA(VLOOKUP(C28,Data!A:G,5,FALSE),"")=0, "Check course registration information", _xlfn.IFNA(VLOOKUP(C28,Data!A:G,5,FALSE),"")) -> Check course registration information | J28: =IF(_xlfn.IFNA(VLOOKUP(C28,Data!A:G,6,FALSE),"")=0, "Check course registration information", _xlfn.IFNA(VLOOKUP(C28,Data!A:G,6,FALSE),"")) -> Check course registration information | K28: =IF(_xlfn.IFNA(VLOOKUP(C28,Data!A:H,7,FALSE),"")=0, "", _xlfn.IFNA(HYPERLINK(VLOOKUP(C28,Data!A:H,7,FALSE),"Catalog Link"),"")) -> Catalog Link | L28: =IF(_xlfn.IFNA(VLOOKUP(C28,Data!A:I,8,FALSE),"")=0, "", _xlfn.IFNA(HYPERLINK(VLOOKUP(C28,Data!A:I,8,FALSE),"Additional Information"),"")) | M28: =COUNTIF(N28:BL28,"x") -> 3 | S28: x | W28: x | BF28: x
A29: No | B29: CHE 59700 | C29: CHE 59700-4 | D29: CHE 59700 Process Synthesis | E29: =IF(_xlfn.IFNA(VLOOKUP(B29,Data!B:G,3,FALSE),"")=0, "", _xlfn.IFNA(VLOOKUP(B29,Data!B:G,3,FALSE),"")) | F29: N/A | H29: =IF(_xlfn.IFNA(VLOOKUP(C29,Data!A:G,5,FALSE),"")=0, "Check course registration information", _xlfn.IFNA(VLOOKUP(C29,Data!A:G,5,FALSE),"")) -> Check course registration information | J29: =IF(_xlfn.IFNA(VLOOKUP(C29,Data!A:G,6,FALSE),"")=0, "Check course registration information", _xlfn.IFNA(VLOOKUP(C29,Data!A:G,6,FALSE),"")) -> Check course registration information | K29: =IF(_xlfn.IFNA(VLOOKUP(C29,Data!A:H,7,FALSE),"")=0, "", _xlfn.IFNA(HYPERLINK(VLOOKUP(C29,Data!A:H,7,FALSE),"Catalog Link"),"")) -> Catalog Link | L29: =IF(_xlfn.IFNA(VLOOKUP(C29,Data!A:I,8,FALSE),"")=0, "", _xlfn.IFNA(HYPERLINK(VLOOKUP(C29,Data!A:I,8,FALSE),"Additional Information"),"")) | M29: =COUNTIF(N29:BL29,"x") -> 3 | X29: x | AS29: x | AY29: x
A30: No | B30: CHE 59700 | C30: CHE 59700-5 | D30: CHE 59700 System Analysis of Energy Prod/ Energy Systems | E30: =IF(_xlfn.IFNA(VLOOKUP(B30,Data!B:G,3,FALSE),"")=0, "", _xlfn.IFNA(VLOOKUP(B30,Data!B:G,3,FALSE),"")) | F30: N/A | H30: =IF(_xlfn.IFNA(VLOOKUP(C30,Data!A:G,5,FALSE),"")=0, "Check course registration information", _xlfn.IFNA(VLOOKUP(C30,Data!A:G,5,FALSE),"")) -> Check course registration information | J30: =IF(_xlfn.IFNA(VLOOKUP(C30,Data!A:G,6,FALSE),"")=0, "Check course registration information", _xlfn.IFNA(VLOOKUP(C30,Data!A:G,6,FALSE),"")) -> Check course registration information | K30: =IF(_xlfn.IFNA(VLOOKUP(C30,Data!A:H,7,FALSE),"")=0, "", _xlfn.IFNA(HYPERLINK(VLOOKUP(C30,Data!A:H,7,FALSE),"Catalog Link"),"")) -> Catalog Link | L30: =IF(_xlfn.IFNA(VLOOKUP(C30,Data!A:I,8,FALSE),"")=0, "", _xlfn.IFNA(HYPERLINK(VLOOKUP(C30,Data!A:I,8,FALSE),"Additional Information"),"")) | M30: =COUNTIF(N30:BL30,"x") -> 1 | AY30: x
A31: No | B31: CHE 59700 | C31: CHE 59700-6 | D31: CHE 59700 Data Science in ChE | E31: =IF(_xlfn.IFNA(VLOOKUP(B31,Data!B:G,3,FALSE),"")=0, "", _xlfn.IFNA(VLOOKUP(B31,Data!B:G,3,FALSE),"")) | F31: N/A | H31: =IF(_xlfn.IFNA(VLOOKUP(C31,Data!A:G,5,FALSE),"")=0, "Check course registration information", _xlfn.IFNA(VLOOKUP(C31,Data!A:G,5,FALSE),"")) -> Check course registration information | J31: =IF(_xlfn.IFNA(VLOOKUP(C31,Data!A:G,6,FALSE),"")=0, "Check course registration information", _xlfn.IFNA(VLOOKUP(C31,Data!A:G,6,FALSE),"")) -> Check course registration information | K31: =IF(_xlfn.IFNA(VLOOKUP(C31,Data!A:H,7,FALSE),"")=0, "", _xlfn.IFNA(HYPERLINK(VLOOKUP(C31,Data!A:H,7,FALSE),"Catalog Link"),"")) -> Catalog Link | L31: =IF(_xlfn.IFNA(VLOOKUP(C31,Data!A:I,8,FALSE),"")=0, "", _xlfn.IFNA(HYPERLINK(VLOOKUP(C31,Data!A:I,8,FALSE),"Additional Information"),"")) | M31: =COUNTIF(N31:BL31,"x") -> 5 | O31: x | U31: x | AY31: x | BD31: x | BK31: x
A32: No | B32: CHE 59700 | C32: CHE 59700-7 | D32: CHE 59700 Manufacturing Advanced Composites | E32: =IF(_xlfn.IFNA(VLOOKUP(B32,Data!B:G,3,FALSE),"")=0, "", _xlfn.IFNA(VLOOKUP(B32,Data!B:G,3,FALSE),"")) | F32: Semiconductor Materials, Characterization, and Processing | H32: =IF(_xlfn.IFNA(VLOOKUP(C32,Data!A:G,5,FALSE),"")=0, "Check course registration information", _xlfn.IFNA(VLOOKUP(C32,Data!A:G,5,FALSE),"")) -> Check course registration information | J32: =IF(_xlfn.IFNA(VLOOKUP(C32,Data!A:G,6,FALSE),"")=0, "Check course registration information", _xlfn.IFNA(VLOOKUP(C32,Data!A:G,6,FALSE),"")) -> Check course registration information | K32: =IF(_xlfn.IFNA(VLOOKUP(C32,Data!A:H,7,FALSE),"")=0, "", _xlfn.IFNA(HYPERLINK(VLOOKUP(C32,Data!A:H,7,FALSE),"Catalog Link"),"")) -> Catalog Link | L32: =IF(_xlfn.IFNA(VLOOKUP(C32,Data!A:I,8,FALSE),"")=0, "", _xlfn.IFNA(HYPERLINK(VLOOKUP(C32,Data!A:I,8,FALSE),"Additional Information"),"")) | M32: =COUNTIF(N32:BL32,"x") -> 0
A33: No | B33: CHE 59700A | C33: CHE 59700A | D33: CHE 59700A Risk Mgmt. Proc. Develop | E33: =IF(_xlfn.IFNA(VLOOKUP(B33,Data!B:G,3,FALSE),"")=0, "", _xlfn.IFNA(VLOOKUP(B33,Data!B:G,3,FALSE),"")) -> 3 | F33: N/A | H33: =IF(_xlfn.IFNA(VLOOKUP(C33,Data!A:G,5,FALSE),"")=0, "Check course registration information", _xlfn.IFNA(VLOOKUP(C33,Data!A:G,5,FALSE),"")) -> Check course registration information | J33: =IF(_xlfn.IFNA(VLOOKUP(C33,Data!A:G,6,FALSE),"")=0, "Check course registration information", _xlfn.IFNA(VLOOKUP(C33,Data!A:G,6,FALSE),"")) -> Legacy information online. | K33: =IF(_xlfn.IFNA(VLOOKUP(C33,Data!A:H,7,FALSE),"")=0, "", _xlfn.IFNA(HYPERLINK(VLOOKUP(C33,Data!A:H,7,FALSE),"Catalog Link"),"")) -> Catalog Link | L33: =IF(_xlfn.IFNA(VLOOKUP(C33,Data!A:I,8,FALSE),"")=0, "", _xlfn.IFNA(HYPERLINK(VLOOKUP(C33,Data!A:I,8,FALSE),"Additional Information"),"")) -> Additional Information | M33: =COUNTIF(N33:BL33,"x") -> 2 | X33: x | AS33: x
A34: No | B34: CHE 59700C | C34: CHE 59700C | D34: CHE 59700C Intro to Energy Stor Sys | E34: 3 | F34: N/A | H34: =IF(_xlfn.IFNA(VLOOKUP(C34,Data!A:G,5,FALSE),"")=0, "Check course registration information", _xlfn.IFNA(VLOOKUP(C34,Data!A:G,5,FALSE),"")) -> Check course registration information | J34: =IF(_xlfn.IFNA(VLOOKUP(C34,Data!A:G,6,FALSE),"")=0, "Check course registration information", _xlfn.IFNA(VLOOKUP(C34,Data!A:G,6,FALSE),"")) -> Now CHE 56000 | K34: =IF(_xlfn.IFNA(VLOOKUP(C34,Data!A:H,7,FALSE),"")=0, "", _xlfn.IFNA(HYPERLINK(VLOOKUP(C34,Data!A:H,7,FALSE),"Catalog Link"),"")) -> Catalog Link | L34: =IF(_xlfn.IFNA(VLOOKUP(C34,Data!A:I,8,FALSE),"")=0, "", _xlfn.IFNA(HYPERLINK(VLOOKUP(C34,Data!A:I,8,FALSE),"Additional Information"),"")) | M34: =COUNTIF(N34:BL34,"x") -> 0
A35: No | B35: CHE 59700N | C35: CHE 59700N | D35: CHE 59700N Intro to Nanoscale | E35: =IF(_xlfn.IFNA(VLOOKUP(B35,Data!B:G,3,FALSE),"")=0, "", _xlfn.IFNA(VLOOKUP(B35,Data!B:G,3,FALSE),"")) -> 3 | F35: N/A | H35: =IF(_xlfn.IFNA(VLOOKUP(C35,Data!A:G,5,FALSE),"")=0, "Check course registration information", _xlfn.IFNA(VLOOKUP(C35,Data!A:G,5,FALSE),"")) -> Check course registration information | J35: =IF(_xlfn.IFNA(VLOOKUP(C35,Data!A:G,6,FALSE),"")=0, "Check course registration information", _xlfn.IFNA(VLOOKUP(C35,Data!A:G,6,FALSE),"")) -> Legacy information online. | K35: =IF(_xlfn.IFNA(VLOOKUP(C35,Data!A:H,7,FALSE),"")=0, "", _xlfn.IFNA(HYPERLINK(VLOOKUP(C35,Data!A:H,7,FALSE),"Catalog Link"),"")) -> Catalog Link | L35: =IF(_xlfn.IFNA(VLOOKUP(C35,Data!A:I,8,FALSE),"")=0, "", _xlfn.IFNA(HYPERLINK(VLOOKUP(C35,Data!A:I,8,FALSE),"Additional Information"),"")) -> Additional Information | M35: =COUNTIF(N35:BL35,"x") -> 4 | N35: x | S35: x | W35: x | BF35: x
A36: No | B36: CHE 59700Q | C36: CHE 59700Q | D36: CHE 59700Q Intr. Quantum Cntrl Engr | E36: =IF(_xlfn.IFNA(VLOOKUP(B36,Data!B:G,3,FALSE),"")=0, "", _xlfn.IFNA(VLOOKUP(B36,Data!B:G,3,FALSE),"")) | F36: N/A | H36: =IF(_xlfn.IFNA(VLOOKUP(C36,Data!A:G,5,FALSE),"")=0, "Check course registration information", _xlfn.IFNA(VLOOKUP(C36,Data!A:G,5,FALSE),"")) -> Check course registration information | J36: =IF(_xlfn.IFNA(VLOOKUP(C36,Data!A:G,6,FALSE),"")=0, "Check course registration information", _xlfn.IFNA(VLOOKUP(C36,Data!A:G,6,FALSE),"")) -> Check course registration information | K36: =IF(_xlfn.IFNA(VLOOKUP(C36,Data!A:H,7,FALSE),"")=0, "", _xlfn.IFNA(HYPERLINK(VLOOKUP(C36,Data!A:H,7,FALSE),"Catalog Link"),"")) -> Catalog Link | L36: =IF(_xlfn.IFNA(VLOOKUP(C36,Data!A:I,8,FALSE),"")=0, "", _xlfn.IFNA(HYPERLINK(VLOOKUP(C36,Data!A:I,8,FALSE),"Additional Information"),"")) | M36: =COUNTIF(N36:BL36,"x") -> 2 | O36: x | AS36: x
A37: No | B37: CHE 59700S | C37: CHE 59700S | D37: CHE 59700S Advanced Solar Conversion | E37: =IF(_xlfn.IFNA(VLOOKUP(B37,Data!B:G,3,FALSE),"")=0, "", _xlfn.IFNA(VLOOKUP(B37,Data!B:G,3,FALSE),"")) | F37: N/A | H37: =IF(_xlfn.IFNA(VLOOKUP(C37,Data!A:G,5,FALSE),"")=0, "Check course registration information", _xlfn.IFNA(VLOOKUP(C37,Data!A:G,5,FALSE),"")) -> Check course registration information | J37: =IF(_xlfn.IFNA(VLOOKUP(C37,Data!A:G,6,FALSE),"")=0, "Check course registration information", _xlfn.IFNA(VLOOKUP(C37,Data!A:G,6,FALSE),"")) -> Check course registration information | K37: =IF(_xlfn.IFNA(VLOOKUP(C37,Data!A:H,7,FALSE),"")=0, "", _xlfn.IFNA(HYPERLINK(VLOOKUP(C37,Data!A:H,7,FALSE),"Catalog Link"),"")) -> Catalog Link | L37: =IF(_xlfn.IFNA(VLOOKUP(C37,Data!A:I,8,FALSE),"")=0, "", _xlfn.IFNA(HYPERLINK(VLOOKUP(C37,Data!A:I,8,FALSE),"Additional Information"),"")) | M37: =COUNTIF(N37:BL37,"x") -> 1 | BF37: x
A38: No | B38: CHM 11500 | C38: CHM 11500 | D38: CHM 11500 General Chemistry-I (UCC: SCI) | E38: =IF(_xlfn.IFNA(VLOOKUP(B38,Data!B:G,3,FALSE),"")=0, "", _xlfn.IFNA(VLOOKUP(B38,Data!B:G,3,FALSE),"")) -> 4 | F38: Semiconductor Materials, Characterization, and Processing | H38: =IF(_xlfn.IFNA(VLOOKUP(C38,Data!A:G,5,FALSE),"")=0, "Check course registration information", _xlfn.IFNA(VLOOKUP(C38,Data!A:G,5,FALSE),"")) -> MA 15900 or MA 15800 or MA 15400 or MATH 15400 or MA 16100 [concurrent ok] or MA 16500 [concurrent ok] or MA 22300 [concurrent ok] or MA 23100 [concurrent ok] or MA 16010 [concurrent ok]) or ALEKS Math Assessment 075 or SATR Math 620 or SAT Mathematics 600 or ACT Math 26 | J38: =IF(_xlfn.IFNA(VLOOKUP(C38,Data!A:G,6,FALSE),"")=0, "Check course registration information", _xlfn.IFNA(VLOOKUP(C38,Data!A:G,6,FALSE),"")) -> Stoichiometry; atomic structure; periodic properties; ionic and covalent bonding; molecular geometry; gases, liquids, and solids; crystal structure; thermochemistry; descriptive chemistry of metals and non-metals. Required of students majoring in science and students in engineering who are not in CHM 12300. One year of high school chemistry or one semester of college chemistry required. CTL:IPS 1721 General Chemistry I w/lab | K38: =IF(_xlfn.IFNA(VLOOKUP(C38,Data!A:H,7,FALSE),"")=0, "", _xlfn.IFNA(HYPERLINK(VLOOKUP(C38,Data!A:H,7,FALSE),"Catalog Link"),"")) -> Catalog Link | L38: =IF(_xlfn.IFNA(VLOOKUP(C38,Data!A:I,8,FALSE),"")=0, "", _xlfn.IFNA(HYPERLINK(VLOOKUP(C38,Data!A:I,8,FALSE),"Additional Information"),"")) | M38: =COUNTIF(N38:BL38,"x") -> 3 | W38: x | AS38: x | BF38: x
A39: No | B39: CHM 11600 | C39: CHM 11600 | D39: CHM 11600 General Chemistry-II (UCC: SCI) | E39: =IF(_xlfn.IFNA(VLOOKUP(B39,Data!B:G,3,FALSE),"")=0, "", _xlfn.IFNA(VLOOKUP(B39,Data!B:G,3,FALSE),"")) -> 4 | F39: Semiconductor Materials, Characterization, and Processing | H39: =IF(_xlfn.IFNA(VLOOKUP(C39,Data!A:G,5,FALSE),"")=0, "Check course registration information", _xlfn.IFNA(VLOOKUP(C39,Data!A:G,5,FALSE),"")) -> CHM 11200 or CHM 11500 or CHM 12500 or CHM 10901 or CHM 12901 or CHM 12300 or CHM 13500 or (CHEM C1050 and CHEM C1250) or (CHEM C1010 and CHEM C1210 | J39: =IF(_xlfn.IFNA(VLOOKUP(C39,Data!A:G,6,FALSE),"")=0, "Check course registration information", _xlfn.IFNA(VLOOKUP(C39,Data!A:G,6,FALSE),"")) -> A continuation of CHM 11500. Solutions; quantitative equilibria in aqueous solution; introductory thermodynamics; oxidation-reduction and electrochemistry; chemical kinetics; qualitative analysis; further descriptive chemistry of metals and nonmetals. CTL:IPS 1722 General Chemistry II w/lab | K39: =IF(_xlfn.IFNA(VLOOKUP(C39,Data!A:H,7,FALSE),"")=0, "", _xlfn.IFNA(HYPERLINK(VLOOKUP(C39,Data!A:H,7,FALSE),"Catalog Link"),"")) -> Catalog Link | L39: =IF(_xlfn.IFNA(VLOOKUP(C39,Data!A:I,8,FALSE),"")=0, "", _xlfn.IFNA(HYPERLINK(VLOOKUP(C39,Data!A:I,8,FALSE),"Additional Information"),"")) | M39: =COUNTIF(N39:BL39,"x") -> 4 | S39: x | W39: x | AS39: x | BF39: x
A40: No | B40: CHM 22404 | C40: CHM 22404 | D40: CHM 22404 Quantitative Analysis | E40: =IF(_xlfn.IFNA(VLOOKUP(B40,Data!B:G,3,FALSE),"")=0, "", _xlfn.IFNA(VLOOKUP(B40,Data!B:G,3,FALSE),"")) -> 3 | F40: N/A | H40: =IF(_xlfn.IFNA(VLOOKUP(C40,Data!A:G,5,FALSE),"")=0, "Check course registration information", _xlfn.IFNA(VLOOKUP(C40,Data!A:G,5,FALSE),"")) -> CHM 11600 or CHM 12600 or CHM 12901 or CHM 13600 or (CHM 11610 and CHM 11620 | J40: =IF(_xlfn.IFNA(VLOOKUP(C40,Data!A:G,6,FALSE),"")=0, "Check course registration information", _xlfn.IFNA(VLOOKUP(C40,Data!A:G,6,FALSE),"")) -> Introduction to approaches analytical chemists use to analyze the composition of matter, including statistics, calibration, and understanding chemical equilibrium (acid/base, complexation, solubility, polyprotic acid treatment, acid/base/redox/precipitation titrations); general approaches to analysis at the trace level; recognition and evaluation of possible sources of error and how error propagates; introduction to how light interacts with matter (and how analytical chemists can take advantage of this) | K40: =IF(_xlfn.IFNA(VLOOKUP(C40,Data!A:H,7,FALSE),"")=0, "", _xlfn.IFNA(HYPERLINK(VLOOKUP(C40,Data!A:H,7,FALSE),"Catalog Link"),"")) -> Catalog Link | L40: =IF(_xlfn.IFNA(VLOOKUP(C40,Data!A:I,8,FALSE),"")=0, "", _xlfn.IFNA(HYPERLINK(VLOOKUP(C40,Data!A:I,8,FALSE),"Additional Information"),"")) | M40: =COUNTIF(N40:BL40,"x") -> 2 | S40: x | BC40: x
...

Sheet Official Courses
A1: =LEFT(B1,FIND("-",B1)-2) -> ECE 30500 | B1: ECE 30500 - Semiconductor Devices Credit Hours: 3.00 | C1: Semiconductor and Microelectronic Devices | H1: =VLOOKUP(A1,Updated!B:D,3,FALSE) -> ECE 30500 Semiconductor Devices | J1: https://catalog.purdue.edu/preview_program.php?catoid=19&poid=35832&hl=%22semiconductor%22&returnto=search
A2: =LEFT(B2,FIND("-",B2)-2) -> ECE 45300 | B2: ECE 45300 - Fundamentals Of Nanoelectronics Credit Hours: 3.00 | C2: Semiconductor and Microelectronic Devices | H2: =VLOOKUP(A2,Updated!B:D,3,FALSE) -> ECE 45300 Fundamentals Of Nanoelectronics
A3: =LEFT(B3,FIND("-",B3)-2) -> ECE 50616 | B3: ECE 50616 - Physics And Manufacturing Of Solar Cells Credit Hours: 3.00 | C3: Semiconductor and Microelectronic Devices | H3: =VLOOKUP(A3,Updated!B:D,3,FALSE) -> ECE 50616 Physics And Manufacturing Of Solar Cells
A4: =LEFT(B4,FIND("-",B4)-2) -> ECE 50631 | B4: ECE 50631 - Fundamentals Of Current Flow Credit Hours: 1.00 | C4: Semiconductor and Microelectronic Devices | H4: =VLOOKUP(A4,Updated!B:D,3,FALSE) -> ECE 50631 Fundamentals Of Current Flow
A5: =LEFT(B5,FIND("-",B5)-2) -> ECE 50632 | B5: ECE 50632 - Introduction To Quantum Transport Credit Hours: 1.00 | C5: Semiconductor and Microelectronic Devices | H5: =VLOOKUP(A5,Updated!B:D,3,FALSE) -> ECE 50632 Introduction to Quantum Transport
A6: =LEFT(B6,FIND("-",B6)-2) -> ECE 50633 | B6: ECE 50633 - Boltzmann Law: Physics To Computing Credit Hours: 1.00 | C6: Semiconductor and Microelectronic Devices | H6: =VLOOKUP(A6,Updated!B:D,3,FALSE) -> ECE 50633 Boltzmann Law: Physics to Machine Learning
A7: =LEFT(B7,FIND("-",B7)-2) -> ECE 50641 | B7: ECE 50641 - Semiconductor Fundamentals Credit Hours: 1.00 | C7: Semiconductor and Microelectronic Devices | H7: =VLOOKUP(A7,Updated!B:D,3,FALSE) -> ECE 50641 Semiconductor Fundamentals
A8: =LEFT(B8,FIND("-",B8)-2) -> ECE 50642 | B8: ECE 50642 - Fundamental Of Transistors Credit Hours: 1.00 | C8: Semiconductor and Microelectronic Devices | H8: =VLOOKUP(A8,Updated!B:D,3,FALSE) -> ECE 50642 Fundamentals of Transistors
A9: =LEFT(B9,FIND("-",B9)-2) -> PHYS 32200 | B9: PHYS 32200 - Intermediate Optics Credit Hours: 3.00 | C9: Semiconductor and Microelectronic Devices | H9: =VLOOKUP(A9,Updated!B:D,3,FALSE) -> PHYS 32200 Intermediate Optics
A10: =LEFT(B10,FIND("-",B10)-2) -> PHYS 34900 | B10: PHYS 34900 - Introduction To Quantum Computing Credit Hours: 3.00 | C10: Semiconductor and Microelectronic Devices | H10: =VLOOKUP(A10,Updated!B:D,3,FALSE) -> PHYS 349 Introduction to Quantum Computing
A11: =LEFT(B11,FIND("-",B11)-2) -> PHYS 45000 | B11: PHYS 45000 - Intermediate Laboratory Credit Hours: 2.00 | C11: Semiconductor and Microelectronic Devices | H11: =VLOOKUP(A11,Updated!B:D,3,FALSE) -> PHYS450: Optics Laboratory I
A12: =LEFT(B12,FIND("-",B12)-2) -> PHYS 52600 | B12: PHYS 52600 - Physics Of Quantum Computing And Quantum Information Credit Hours: 3.00 | C12: Semiconductor and Microelectronic Devices | H12: =VLOOKUP(A12,Updated!B:D,3,FALSE) -> PHYS 526 Physics Of Quantum Computing And Quantum Information
A13: =LEFT(B13,FIND("-",B13)-2) -> PHYS 54500 | B13: PHYS 54500 - Solid-State Physics Credit Hours: 3.00 | C13: Semiconductor and Microelectronic Devices | H13: =VLOOKUP(A13,Updated!B:D,3,FALSE) -> PHYS 545 Solid State Physics
... A67: =LEFT(B67,FIND("-",B67)-2) -> SCOM 46300 | B67: SCOM 46300 - Supply Chain Analytics Credit Hours: 3.00 | C67: Semiconductor Manufacturing and Global Supply Chain Management | H67: =VLOOKUP(A67,Updated!B:D,3,FALSE) -> SCOM 46300 Supply Chain Analytics

Sheet Data
A1: Certificate Course Number | B1: Course Number | C1: Course | D1: Credits | E1: Pre-Requisites | F1: Course Description | G1: Catalog Link | H1: Additional Information
A2: CHE 20500 | B2: CHE 20500 | C2: CHE 20500 Chemical Engineering Calculations | D2: 4 | E2: ENGR 12100 or ENFY 12600 or ENGR 12600 or ENFY 13100 or ENGR 13100 or ENGR 13000 or VIP 17911 or ENGR 17911 or ENGR 16100 or EPCS 11100 or EPCS 12100 or ENFY 19500 or ENGR 19500 or ENGR 14100 or ENGR 16100) and (PHYS 17200 or (PHYS 16200 and PHYS 16300) or (ENGR 16200) and (MA 16100 or MA 16700 Minimum Grade of | F2: Quantitative applications of steady-state mass and energy balances to solve problems involving multi-component systems and multi-unit chemical processes. Single-component and multi-component phase equilibria, single-reaction and multiple-reaction stoichiometry, coupled mass and energy balances, chemical processes involving bypass and recycle streams | G2: https://selfservice.mypurdue.purdue.edu/prod/bwckctlg.p_disp_course_detail?cat_term_in=202710&subj_code_in=CHE&crse_numb_in=20500
A3: CHE 21100 | B3: CHE 21100 | C3: CHE 21100 Introductory Chemical Engineering Thermodynamics | D3: 4 | E3: CHE 20500 and (MA 26100 or MATH 26100 or MA 18200 or MA 17400 or MA 27100 or MA 26300 or MA 17200 | F3: Basic principles and concepts of thermodynamics applied to chemical engineering problems; use of basic thermodynamic functions of enthalpy, entropy, free energy to solutions, phase equilibria, and chemical equilibria; thermodynamic processes and efficiencies; equations of state; and relation of macroscopic to molecular properties | G3: https://selfservice.mypurdue.purdue.edu/prod/bwckctlg.p_disp_course_detail?cat_term_in=202710&subj_code_in=CHE&crse_numb_in=21100
A4: CHE 30600 | B4: CHE 30600 | C4: CHE 30600 Design Of Staged Separation Processes | D4: 3 | E4: CHE 20500 and CHE 21100 | F4: The application of equilibria and mass and energy balances for the design of staged separation processes. Use of various equilibrium data and thermodynamic principles for the design of batch and continuous distillation, absorption, stripping, and extraction systems. Stagewise calculations and graphical methods for design of binary systems. Design of multicomponent separators. Determination of stage efficiency and column size | G4: https://selfservice.mypurdue.purdue.edu/prod/bwckctlg.p_disp_course_detail?cat_term_in=202710&subj_code_in=CHE&crse_numb_in=30600
A5: CHE 32000 | B5: CHE 32000 | C5: CHE 32000 Statistical Modeling And Quality Enhancement | D5: 3 | E5: CHE 20500 or ABE 20100) and MA 26100 [concurrent ok] and (CHM 26100 or CHM 25500 [concurrent ok] or CHM 25700 [concurrent ok]) and (MA 26200 [concurrent ok] or MATH 26200 or MA 26500 [concurrent ok] or MA 35100 [concurrent ok] | F5: Statistical modeling methods, design of experiments, error analysis, curve fitting and regression, analysis of variance, confidence intervals, quality control and enhancement: emphasizes preparation for designing chemical engineering laboratory experiments and analyzing data | G5: https://selfservice.mypurdue.purdue.edu/prod/bwckctlg.p_disp_course_detail?cat_term_in=202710&subj_code_in=CHE&crse_numb_in=32000
A6: CHE 34800 | B6: CHE 34800 | C6: CHE 34800 Chemical Reaction Engineering | D6: 4 | E6: CHE 21100 and (MA 26600 [concurrent ok] or MA 30300 [concurrent ok] or MA 36600 [concurrent ok] or ME 58100 [concurrent ok] or MA 51400 [concurrent ok] | F6: Application of kinetic rate equations, mass balances and energy balances to the analysis and design of chemical reactors involving homogeneous and heterogeneous chemical reactions. Chemical equilibria, kinetic rate equations for homogeneous and heterogeneously catalyzed reactions, design of ideal isothermal reactors, effects of non-isothermal operation, effects of diffusion in porous catalysts and non-ideal mixing in continuous flow reactors | G6: https://selfservice.mypurdue.purdue.edu/prod/bwckctlg.p_disp_course_detail?cat_term_in=202710&subj_code_in=CHE&crse_numb_in=34800
A7: CHE 37700 | B7: CHE 37700 | C7: CHE 37700 Momentum Transfer | D7: 4 | E7: CHE 21100 and (MA 26600 [concurrent ok] or MA 30300 [concurrent ok] or MA 36600 [concurrent ok] or MA 51400 [concurrent ok] or ME 58100 [concurrent ok] | F7: Differential (microscopic) and integral (macroscopic) mass, momentum, and energy balances. Newtonian and non-Newtonian fluids. Fluid statics. One-dimensional steady and transient laminar flows. Turbulence. Dimensional analysis and similarity. Friction factors and drag coefficients. Applications to engineering analysis of practical problems. Introduction to numerical analysis and visualization of flows | G7: https://selfservice.mypurdue.purdue.edu/prod/bwckctlg.p_disp_course_detail?cat_term_in=202710&subj_code_in=CHE&crse_numb_in=37700
A8: CHE 37800 | B8: CHE 37800 | C8: CHE 37800 Heat And Mass Transfer | D8: 4 | E8: CHE 21100 and CHE 37700 | F8: Macroscopic and differential energy balances. Heat transfer coefficients for free and forced convection and phase change. Conductive and radiative heat transfer. Applications to heat transfer equipment design and compressible fluid flow. Macroscopic and differential species balances. Mass transfer coefficients and analogies. Mass transfer with and without chemical reaction. Mass transfer equipment design | G8: https://selfservice.mypurdue.purdue.edu/prod/bwckctlg.p_disp_course_detail?cat_term_in=202710&subj_code_in=CHE&crse_numb_in=37800
A9: CHE 42000 | B9: CHE 42000 | C9: CHE 42000 Process Safety Management And Analysis | D9: 3 | E9: CHE 34800 [concurrent ok] and CHE 37800 [concurrent ok] | F9: Develop knowledge of process safety management and analysis in the process industries, including hazard identification, hazard analysis and risk management | G9: https://selfservice.mypurdue.purdue.edu/prod/bwckctlg.p_disp_course_detail?cat_term_in=202710&subj_code_in=CHE&crse_numb_in=42000
A10: CHE 43500 | B10: CHE 43500 | C10: CHE 43500 Chemical Engineering Laboratory | D10: 4 | E10: CHE 32000 and CHE 34800 and CHE 37800 and CHE 30600 | F10: Quantitative experimental study of projects involving problems in fluid mechanics and heat and mass transfer or operation and evaluation of equipment; projects include analysis and data-based design of operations involving mass transfer such as distillation, absorption, drying, humidification, etc.; study of rates and equilibria in simple chemical reaction systems; study of chemical processes; application of methods of data analysis in practice; some library work; emphasis on group work, report writing, and oral communication | G10: https://selfservice.mypurdue.purdue.edu/prod/bwckctlg.p_disp_course_detail?cat_term_in=202710&subj_code_in=CHE&crse_numb_in=43500
A11: CHE 45000 | B11: CHE 45000 | C11: CHE 45000 Design And Analysis Of Processing Systems | D11: 4 | E11: CHE 30600 and CHE 37800 and CHE 42000 and CHE 45600 and CHE 43500 [concurrent ok] | F11: Use of process synthesis methods and concepts; detailed design of unit operation equipment, the economics of chemical plants and flow sheet optimization methods. Synthesize, develop, and evaluate a preliminary design of a chemical process that meets market requirements for a specific product. Analysis of design alternatives using case studies and optimization methods | G11: https://selfservice.mypurdue.purdue.edu/prod/bwckctlg.p_disp_course_detail?cat_term_in=202710&subj_code_in=CHE&crse_numb_in=45000
